[2023-07-24 10:01:05,490] {taskinstance.py:1159} INFO - Dependencies all met for <TaskInstance: etl_dag.fetch_data manual__2023-07-24T10:00:52.685786+00:00 [queued]>
[2023-07-24 10:01:05,639] {taskinstance.py:1159} INFO - Dependencies all met for <TaskInstance: etl_dag.fetch_data manual__2023-07-24T10:00:52.685786+00:00 [queued]>
[2023-07-24 10:01:05,649] {taskinstance.py:1356} INFO - 
--------------------------------------------------------------------------------
[2023-07-24 10:01:05,661] {taskinstance.py:1357} INFO - Starting attempt 1 of 1
[2023-07-24 10:01:05,666] {taskinstance.py:1358} INFO - 
--------------------------------------------------------------------------------
[2023-07-24 10:01:06,010] {taskinstance.py:1377} INFO - Executing <Task(PythonOperator): fetch_data> on 2023-07-24 10:00:52.685786+00:00
[2023-07-24 10:01:06,379] {standard_task_runner.py:79} INFO - Running: ['***', 'tasks', 'run', 'etl_dag', 'fetch_data', 'manual__2023-07-24T10:00:52.685786+00:00', '--job-id', '15', '--raw', '--subdir', 'DAGS_FOLDER/etl_dag.py', '--cfg-path', '/tmp/tmp6lewtunj', '--error-file', '/tmp/tmpajnb2la5']
[2023-07-24 10:01:06,230] {standard_task_runner.py:52} INFO - Started process 557 to run task
[2023-07-24 10:01:06,407] {standard_task_runner.py:80} INFO - Job 15: Subtask fetch_data
[2023-07-24 10:01:06,964] {task_command.py:370} INFO - Running <TaskInstance: etl_dag.fetch_data manual__2023-07-24T10:00:52.685786+00:00 [running]> on host c03236539c84
[2023-07-24 10:01:07,473] {taskinstance.py:1571} INFO - Exporting the following env vars:
AIRFLOW_CTX_DAG_OWNER=***
AIRFLOW_CTX_DAG_ID=etl_dag
AIRFLOW_CTX_TASK_ID=fetch_data
AIRFLOW_CTX_EXECUTION_DATE=2023-07-24T10:00:52.685786+00:00
AIRFLOW_CTX_TRY_NUMBER=1
AIRFLOW_CTX_DAG_RUN_ID=manual__2023-07-24T10:00:52.685786+00:00
[2023-07-24 10:01:08,290] {base.py:68} INFO - Using connection ID 'aws_default' for task execution.
[2023-07-24 10:01:08,298] {base_aws.py:206} INFO - Credentials retrieved from login
[2023-07-24 10:01:19,213] {taskinstance.py:1889} ERROR - Task failed with exception
Traceback (most recent call last):
  File "/home/airflow/.local/lib/python3.7/site-packages/airflow/operators/python.py", line 171, in execute
    return_value = self.execute_callable()
  File "/home/airflow/.local/lib/python3.7/site-packages/airflow/operators/python.py", line 189, in execute_callable
    return self.python_callable(*self.op_args, **self.op_kwargs)
  File "/opt/airflow/dags/etl_dag.py", line 63, in _fetch_data_upload_S3
    s3_hook.load_file(filename=file, key=filename, bucket_name=Variable.get("S3BucketName"))
  File "/home/airflow/.local/lib/python3.7/site-packages/airflow/providers/amazon/aws/hooks/s3.py", line 63, in wrapper
    return func(*bound_args.args, **bound_args.kwargs)
  File "/home/airflow/.local/lib/python3.7/site-packages/airflow/providers/amazon/aws/hooks/s3.py", line 91, in wrapper
    return func(*bound_args.args, **bound_args.kwargs)
  File "/home/airflow/.local/lib/python3.7/site-packages/airflow/providers/amazon/aws/hooks/s3.py", line 615, in load_file
    client.upload_file(filename, bucket_name, key, ExtraArgs=extra_args, Config=self.transfer_config)
  File "/home/airflow/.local/lib/python3.7/site-packages/boto3/s3/inject.py", line 148, in upload_file
    callback=Callback,
  File "/home/airflow/.local/lib/python3.7/site-packages/boto3/s3/transfer.py", line 288, in upload_file
    future.result()
  File "/home/airflow/.local/lib/python3.7/site-packages/s3transfer/futures.py", line 103, in result
    return self._coordinator.result()
  File "/home/airflow/.local/lib/python3.7/site-packages/s3transfer/futures.py", line 266, in result
    raise self._exception
  File "/home/airflow/.local/lib/python3.7/site-packages/s3transfer/tasks.py", line 269, in _main
    self._submit(transfer_future=transfer_future, **kwargs)
  File "/home/airflow/.local/lib/python3.7/site-packages/s3transfer/upload.py", line 585, in _submit
    upload_input_manager.provide_transfer_size(transfer_future)
  File "/home/airflow/.local/lib/python3.7/site-packages/s3transfer/upload.py", line 244, in provide_transfer_size
    self._osutil.get_file_size(transfer_future.meta.call_args.fileobj)
  File "/home/airflow/.local/lib/python3.7/site-packages/s3transfer/utils.py", line 247, in get_file_size
    return os.path.getsize(filename)
  File "/usr/local/lib/python3.7/genericpath.py", line 50, in getsize
    return os.stat(filename).st_size
OSError: [Errno 36] File name too long: '                cc_num  ... prediction\n0     3549202406645667  ...          1\n1  4512828414983801773  ...          1\n2     3519607465576254  ...          1\n3     4377338765909719  ...          1\n4      378904938837132  ...          1\n\n[5 rows x 24 columns]'
[2023-07-24 10:01:19,349] {taskinstance.py:1400} INFO - Marking task as FAILED. dag_id=etl_dag, task_id=fetch_data, execution_date=20230724T100052, start_date=20230724T100105, end_date=20230724T100119
[2023-07-24 10:01:19,487] {standard_task_runner.py:97} ERROR - Failed to execute job 15 for task fetch_data ([Errno 36] File name too long: '                cc_num  ... prediction\n0     3549202406645667  ...          1\n1  4512828414983801773  ...          1\n2     3519607465576254  ...          1\n3     4377338765909719  ...          1\n4      378904938837132  ...          1\n\n[5 rows x 24 columns]'; 557)
[2023-07-24 10:01:19,702] {local_task_job.py:156} INFO - Task exited with return code 1
[2023-07-24 10:01:20,198] {local_task_job.py:273} INFO - 0 downstream tasks scheduled from follow-on schedule check
