[2023-07-24 12:32:01,783] {taskinstance.py:1159} INFO - Dependencies all met for <TaskInstance: etl_dag.detect_file manual__2023-07-24T12:31:22.193345+00:00 [queued]>
[2023-07-24 12:32:02,256] {taskinstance.py:1159} INFO - Dependencies all met for <TaskInstance: etl_dag.detect_file manual__2023-07-24T12:31:22.193345+00:00 [queued]>
[2023-07-24 12:32:02,269] {taskinstance.py:1356} INFO - 
--------------------------------------------------------------------------------
[2023-07-24 12:32:02,271] {taskinstance.py:1357} INFO - Starting attempt 1 of 1
[2023-07-24 12:32:02,298] {taskinstance.py:1358} INFO - 
--------------------------------------------------------------------------------
[2023-07-24 12:32:02,794] {taskinstance.py:1377} INFO - Executing <Task(PythonSensor): detect_file> on 2023-07-24 12:31:22.193345+00:00
[2023-07-24 12:32:02,959] {standard_task_runner.py:52} INFO - Started process 5471 to run task
[2023-07-24 12:32:03,110] {standard_task_runner.py:79} INFO - Running: ['***', 'tasks', 'run', 'etl_dag', 'detect_file', 'manual__2023-07-24T12:31:22.193345+00:00', '--job-id', '93', '--raw', '--subdir', 'DAGS_FOLDER/etl_dag.py', '--cfg-path', '/tmp/tmptz1ct0yq', '--error-file', '/tmp/tmp9jqrn7nj']
[2023-07-24 12:32:03,169] {standard_task_runner.py:80} INFO - Job 93: Subtask detect_file
[2023-07-24 12:32:06,097] {task_command.py:370} INFO - Running <TaskInstance: etl_dag.detect_file manual__2023-07-24T12:31:22.193345+00:00 [running]> on host c03236539c84
[2023-07-24 12:32:10,899] {taskinstance.py:1889} ERROR - Task failed with exception
Traceback (most recent call last):
  File "/home/airflow/.local/lib/python3.7/site-packages/sqlalchemy/engine/base.py", line 1706, in _execute_context
    cursor, statement, parameters, context
  File "/home/airflow/.local/lib/python3.7/site-packages/sqlalchemy/engine/default.py", line 716, in do_execute
    cursor.execute(statement, parameters)
psycopg2.errors.ForeignKeyViolation: insert or update on table "rendered_task_instance_fields" violates foreign key constraint "rtif_ti_fkey"
DETAIL:  Key (dag_id, task_id, run_id, map_index)=(etl_dag, detect_file, manual__2023-07-24T12:31:22.193345+00:00, -1) is not present in table "task_instance".


The above exception was the direct cause of the following exception:

Traceback (most recent call last):
  File "/home/airflow/.local/lib/python3.7/site-packages/airflow/models/taskinstance.py", line 1451, in _run_raw_task
    self._execute_task_with_callbacks(context, test_mode)
  File "/home/airflow/.local/lib/python3.7/site-packages/airflow/models/taskinstance.py", line 1558, in _execute_task_with_callbacks
    RenderedTaskInstanceFields.write(rtif)
  File "/home/airflow/.local/lib/python3.7/site-packages/airflow/utils/session.py", line 71, in wrapper
    return func(*args, session=session, **kwargs)
  File "/usr/local/lib/python3.7/contextlib.py", line 119, in __exit__
    next(self.gen)
  File "/home/airflow/.local/lib/python3.7/site-packages/airflow/utils/session.py", line 33, in create_session
    session.commit()
  File "/home/airflow/.local/lib/python3.7/site-packages/sqlalchemy/orm/session.py", line 1423, in commit
    self._transaction.commit(_to_root=self.future)
  File "/home/airflow/.local/lib/python3.7/site-packages/sqlalchemy/orm/session.py", line 829, in commit
    self._prepare_impl()
  File "/home/airflow/.local/lib/python3.7/site-packages/sqlalchemy/orm/session.py", line 808, in _prepare_impl
    self.session.flush()
  File "/home/airflow/.local/lib/python3.7/site-packages/sqlalchemy/orm/session.py", line 3255, in flush
    self._flush(objects)
  File "/home/airflow/.local/lib/python3.7/site-packages/sqlalchemy/orm/session.py", line 3395, in _flush
    transaction.rollback(_capture_exception=True)
  File "/home/airflow/.local/lib/python3.7/site-packages/sqlalchemy/util/langhelpers.py", line 72, in __exit__
    with_traceback=exc_tb,
  File "/home/airflow/.local/lib/python3.7/site-packages/sqlalchemy/util/compat.py", line 211, in raise_
    raise exception
  File "/home/airflow/.local/lib/python3.7/site-packages/sqlalchemy/orm/session.py", line 3355, in _flush
    flush_context.execute()
  File "/home/airflow/.local/lib/python3.7/site-packages/sqlalchemy/orm/unitofwork.py", line 453, in execute
    rec.execute(self)
  File "/home/airflow/.local/lib/python3.7/site-packages/sqlalchemy/orm/unitofwork.py", line 630, in execute
    uow,
  File "/home/airflow/.local/lib/python3.7/site-packages/sqlalchemy/orm/persistence.py", line 247, in save_obj
    insert,
  File "/home/airflow/.local/lib/python3.7/site-packages/sqlalchemy/orm/persistence.py", line 1095, in _emit_insert_statements
    statement, multiparams, execution_options=execution_options
  File "/home/airflow/.local/lib/python3.7/site-packages/sqlalchemy/engine/base.py", line 1520, in _execute_20
    return meth(self, args_10style, kwargs_10style, execution_options)
  File "/home/airflow/.local/lib/python3.7/site-packages/sqlalchemy/sql/elements.py", line 314, in _execute_on_connection
    self, multiparams, params, execution_options
  File "/home/airflow/.local/lib/python3.7/site-packages/sqlalchemy/engine/base.py", line 1399, in _execute_clauseelement
    cache_hit=cache_hit,
  File "/home/airflow/.local/lib/python3.7/site-packages/sqlalchemy/engine/base.py", line 1749, in _execute_context
    e, statement, parameters, cursor, context
  File "/home/airflow/.local/lib/python3.7/site-packages/sqlalchemy/engine/base.py", line 1930, in _handle_dbapi_exception
    sqlalchemy_exception, with_traceback=exc_info[2], from_=e
  File "/home/airflow/.local/lib/python3.7/site-packages/sqlalchemy/util/compat.py", line 211, in raise_
    raise exception
  File "/home/airflow/.local/lib/python3.7/site-packages/sqlalchemy/engine/base.py", line 1706, in _execute_context
    cursor, statement, parameters, context
  File "/home/airflow/.local/lib/python3.7/site-packages/sqlalchemy/engine/default.py", line 716, in do_execute
    cursor.execute(statement, parameters)
sqlalchemy.exc.IntegrityError: (psycopg2.errors.ForeignKeyViolation) insert or update on table "rendered_task_instance_fields" violates foreign key constraint "rtif_ti_fkey"
DETAIL:  Key (dag_id, task_id, run_id, map_index)=(etl_dag, detect_file, manual__2023-07-24T12:31:22.193345+00:00, -1) is not present in table "task_instance".

[SQL: INSERT INTO rendered_task_instance_fields (dag_id, task_id, run_id, map_index, rendered_fields, k8s_pod_yaml) VALUES (%(dag_id)s, %(task_id)s, %(run_id)s, %(map_index)s, %(rendered_fields)s, %(k8s_pod_yaml)s)]
[parameters: {'dag_id': 'etl_dag', 'task_id': 'detect_file', 'run_id': 'manual__2023-07-24T12:31:22.193345+00:00', 'map_index': -1, 'rendered_fields': '{"templates_dict": null, "op_args": [], "op_kwargs": {}}', 'k8s_pod_yaml': 'null'}]
(Background on this error at: http://sqlalche.me/e/14/gkpj)
[2023-07-24 12:32:13,445] {taskinstance.py:1400} INFO - Marking task as FAILED. dag_id=etl_dag, task_id=detect_file, execution_date=20230724T123122, start_date=20230724T123201, end_date=20230724T123213
[2023-07-24 12:32:15,071] {standard_task_runner.py:97} ERROR - Failed to execute job 93 for task detect_file ((psycopg2.errors.ForeignKeyViolation) insert or update on table "task_fail" violates foreign key constraint "task_fail_ti_fkey"
DETAIL:  Key (dag_id, task_id, run_id, map_index)=(etl_dag, detect_file, manual__2023-07-24T12:31:22.193345+00:00, -1) is not present in table "task_instance".

[SQL: INSERT INTO task_fail (task_id, dag_id, run_id, map_index, start_date, end_date, duration) VALUES (%(task_id)s, %(dag_id)s, %(run_id)s, %(map_index)s, %(start_date)s, %(end_date)s, %(duration)s) RETURNING task_fail.id]
[parameters: {'task_id': 'detect_file', 'dag_id': 'etl_dag', 'run_id': 'manual__2023-07-24T12:31:22.193345+00:00', 'map_index': -1, 'start_date': datetime.datetime(2023, 7, 24, 12, 32, 1, 799245, tzinfo=Timezone('UTC')), 'end_date': datetime.datetime(2023, 7, 24, 12, 32, 13, 428736, tzinfo=Timezone('UTC')), 'duration': 11}]
(Background on this error at: http://sqlalche.me/e/14/gkpj); 5471)
[2023-07-24 12:32:15,823] {local_task_job.py:156} INFO - Task exited with return code 1
