[2023-07-24 10:28:09,809] {taskinstance.py:1159} INFO - Dependencies all met for <TaskInstance: etl_dag.fetch_data manual__2023-07-24T10:27:59.733959+00:00 [queued]>
[2023-07-24 10:28:09,925] {taskinstance.py:1159} INFO - Dependencies all met for <TaskInstance: etl_dag.fetch_data manual__2023-07-24T10:27:59.733959+00:00 [queued]>
[2023-07-24 10:28:09,927] {taskinstance.py:1356} INFO - 
--------------------------------------------------------------------------------
[2023-07-24 10:28:09,935] {taskinstance.py:1357} INFO - Starting attempt 1 of 1
[2023-07-24 10:28:09,944] {taskinstance.py:1358} INFO - 
--------------------------------------------------------------------------------
[2023-07-24 10:28:10,385] {taskinstance.py:1377} INFO - Executing <Task(PythonOperator): fetch_data> on 2023-07-24 10:27:59.733959+00:00
[2023-07-24 10:28:10,483] {standard_task_runner.py:52} INFO - Started process 1453 to run task
[2023-07-24 10:28:10,585] {standard_task_runner.py:79} INFO - Running: ['***', 'tasks', 'run', 'etl_dag', 'fetch_data', 'manual__2023-07-24T10:27:59.733959+00:00', '--job-id', '31', '--raw', '--subdir', 'DAGS_FOLDER/etl_dag.py', '--cfg-path', '/tmp/tmpiea3h2hu', '--error-file', '/tmp/tmp79u1lyc4']
[2023-07-24 10:28:10,592] {standard_task_runner.py:80} INFO - Job 31: Subtask fetch_data
[2023-07-24 10:28:10,985] {task_command.py:370} INFO - Running <TaskInstance: etl_dag.fetch_data manual__2023-07-24T10:27:59.733959+00:00 [running]> on host c03236539c84
[2023-07-24 10:28:11,415] {taskinstance.py:1571} INFO - Exporting the following env vars:
AIRFLOW_CTX_DAG_OWNER=***
AIRFLOW_CTX_DAG_ID=etl_dag
AIRFLOW_CTX_TASK_ID=fetch_data
AIRFLOW_CTX_EXECUTION_DATE=2023-07-24T10:27:59.733959+00:00
AIRFLOW_CTX_TRY_NUMBER=1
AIRFLOW_CTX_DAG_RUN_ID=manual__2023-07-24T10:27:59.733959+00:00
[2023-07-24 10:28:11,580] {base.py:68} INFO - Using connection ID 'aws_default' for task execution.
[2023-07-24 10:28:11,589] {base_aws.py:206} INFO - Credentials retrieved from login
[2023-07-24 10:28:14,207] {taskinstance.py:1889} ERROR - Task failed with exception
Traceback (most recent call last):
  File "/home/airflow/.local/lib/python3.7/site-packages/airflow/operators/python.py", line 171, in execute
    return_value = self.execute_callable()
  File "/home/airflow/.local/lib/python3.7/site-packages/airflow/operators/python.py", line 189, in execute_callable
    return self.python_callable(*self.op_args, **self.op_kwargs)
  File "/opt/airflow/dags/etl_dag.py", line 62, in _fetch_data_upload_S3
    s3_hook.load_file(filename=data_logs_filename, key=filename, bucket_name=Variable.get("S3BucketName"))
  File "/home/airflow/.local/lib/python3.7/site-packages/airflow/providers/amazon/aws/hooks/s3.py", line 63, in wrapper
    return func(*bound_args.args, **bound_args.kwargs)
  File "/home/airflow/.local/lib/python3.7/site-packages/airflow/providers/amazon/aws/hooks/s3.py", line 91, in wrapper
    return func(*bound_args.args, **bound_args.kwargs)
  File "/home/airflow/.local/lib/python3.7/site-packages/airflow/providers/amazon/aws/hooks/s3.py", line 600, in load_file
    raise ValueError(f"The key {key} already exists.")
ValueError: The key Real_time_payments_1690187507.8259003.csv already exists.
[2023-07-24 10:28:14,317] {taskinstance.py:1400} INFO - Marking task as FAILED. dag_id=etl_dag, task_id=fetch_data, execution_date=20230724T102759, start_date=20230724T102809, end_date=20230724T102814
[2023-07-24 10:28:14,534] {standard_task_runner.py:97} ERROR - Failed to execute job 31 for task fetch_data (The key Real_time_payments_1690187507.8259003.csv already exists.; 1453)
[2023-07-24 10:28:14,747] {local_task_job.py:156} INFO - Task exited with return code 1
[2023-07-24 10:28:15,322] {local_task_job.py:273} INFO - 0 downstream tasks scheduled from follow-on schedule check
