[2023-07-24 12:00:03,432] {taskinstance.py:1159} INFO - Dependencies all met for <TaskInstance: etl_dag.move_data_to_another_table manual__2023-07-24T11:59:54.154456+00:00 [queued]>
[2023-07-24 12:00:04,137] {taskinstance.py:1159} INFO - Dependencies all met for <TaskInstance: etl_dag.move_data_to_another_table manual__2023-07-24T11:59:54.154456+00:00 [queued]>
[2023-07-24 12:00:04,150] {taskinstance.py:1356} INFO - 
--------------------------------------------------------------------------------
[2023-07-24 12:00:04,207] {taskinstance.py:1357} INFO - Starting attempt 1 of 1
[2023-07-24 12:00:04,214] {taskinstance.py:1358} INFO - 
--------------------------------------------------------------------------------
[2023-07-24 12:00:05,408] {taskinstance.py:1377} INFO - Executing <Task(PostgresOperator): move_data_to_another_table> on 2023-07-24 11:59:54.154456+00:00
[2023-07-24 12:00:05,658] {standard_task_runner.py:52} INFO - Started process 4397 to run task
[2023-07-24 12:00:05,966] {standard_task_runner.py:79} INFO - Running: ['***', 'tasks', 'run', 'etl_dag', 'move_data_to_another_table', 'manual__2023-07-24T11:59:54.154456+00:00', '--job-id', '49', '--raw', '--subdir', 'DAGS_FOLDER/etl_dag.py', '--cfg-path', '/tmp/tmpl18mea3q', '--error-file', '/tmp/tmpziid2mxv']
[2023-07-24 12:00:06,048] {standard_task_runner.py:80} INFO - Job 49: Subtask move_data_to_another_table
[2023-07-24 12:00:08,805] {task_command.py:370} INFO - Running <TaskInstance: etl_dag.move_data_to_another_table manual__2023-07-24T11:59:54.154456+00:00 [running]> on host c03236539c84
[2023-07-24 12:00:13,328] {taskinstance.py:1571} INFO - Exporting the following env vars:
AIRFLOW_CTX_DAG_OWNER=***
AIRFLOW_CTX_DAG_ID=etl_dag
AIRFLOW_CTX_TASK_ID=move_data_to_another_table
AIRFLOW_CTX_EXECUTION_DATE=2023-07-24T11:59:54.154456+00:00
AIRFLOW_CTX_TRY_NUMBER=1
AIRFLOW_CTX_DAG_RUN_ID=manual__2023-07-24T11:59:54.154456+00:00
[2023-07-24 12:00:13,441] {base.py:68} INFO - Using connection ID 'postgres://cazwrmravtstuq:***@ec2-54-234-13-16.compute-1.amazonaws.com:5432/d7ojfso4s2fmat' for task execution.
[2023-07-24 12:00:14,271] {dbapi.py:213} INFO - Running statement: INSERT INTO public.fraudtest_new (trans_date_trans_time, cc_num, merchant, category, amt, first, last, gender, street, city, state, zip, lat, long, city_pop, job, dob, trans_num, unix_time, merch_lat, merch_long, is_fraud, prediction) SELECT trans_date_trans_time, cc_num, merchant, category, amt, first, last, gender, street, city, state, zip, lat, long, city_pop, job, dob, trans_num, unix_time, merch_lat, merch_long, is_fraud, prediction FROM real_time_data;, parameters: None
[2023-07-24 12:00:14,467] {taskinstance.py:1889} ERROR - Task failed with exception
Traceback (most recent call last):
  File "/home/airflow/.local/lib/python3.7/site-packages/airflow/providers/postgres/operators/postgres.py", line 92, in execute
    self.hook.run(self.sql, self.autocommit, parameters=self.parameters)
  File "/home/airflow/.local/lib/python3.7/site-packages/airflow/hooks/dbapi.py", line 193, in run
    self._run_command(cur, sql_statement, parameters)
  File "/home/airflow/.local/lib/python3.7/site-packages/airflow/hooks/dbapi.py", line 217, in _run_command
    cur.execute(sql_statement)
psycopg2.errors.UndefinedTable: relation "real_time_data" does not exist
LINE 1: ... merch_lat, merch_long, is_fraud, prediction FROM real_time_...
                                                             ^

[2023-07-24 12:00:17,990] {taskinstance.py:1400} INFO - Marking task as FAILED. dag_id=etl_dag, task_id=move_data_to_another_table, execution_date=20230724T115954, start_date=20230724T120003, end_date=20230724T120017
[2023-07-24 12:00:18,716] {standard_task_runner.py:97} ERROR - Failed to execute job 49 for task move_data_to_another_table (relation "real_time_data" does not exist
LINE 1: ... merch_lat, merch_long, is_fraud, prediction FROM real_time_...
                                                             ^
; 4397)
[2023-07-24 12:00:19,224] {local_task_job.py:156} INFO - Task exited with return code 1
[2023-07-24 12:00:20,201] {local_task_job.py:273} INFO - 0 downstream tasks scheduled from follow-on schedule check
[2023-07-24 12:00:20,777] {dagrun.py:562} INFO - Marking run <DagRun etl_dag @ 2023-07-24 11:59:54.154456+00:00: manual__2023-07-24T11:59:54.154456+00:00, externally triggered: True> successful
[2023-07-24 12:00:20,815] {dagrun.py:622} INFO - DagRun Finished: dag_id=etl_dag, execution_date=2023-07-24 11:59:54.154456+00:00, run_id=manual__2023-07-24T11:59:54.154456+00:00, run_start_date=2023-07-24 11:59:55.267486+00:00, run_end_date=2023-07-24 12:00:20.789139+00:00, run_duration=25.521653, state=success, external_trigger=True, run_type=manual, data_interval_start=2023-07-24 10:00:00+00:00, data_interval_end=2023-07-24 11:00:00+00:00, dag_hash=957bb6d4b63e6eb21d63f788501de800
