[2023-07-24 12:02:13,758] {taskinstance.py:1159} INFO - Dependencies all met for <TaskInstance: etl_dag.fetch_data manual__2023-07-24T12:01:56.805305+00:00 [queued]>
[2023-07-24 12:02:13,795] {taskinstance.py:1159} INFO - Dependencies all met for <TaskInstance: etl_dag.fetch_data manual__2023-07-24T12:01:56.805305+00:00 [queued]>
[2023-07-24 12:02:13,801] {taskinstance.py:1356} INFO - 
--------------------------------------------------------------------------------
[2023-07-24 12:02:13,803] {taskinstance.py:1357} INFO - Starting attempt 1 of 1
[2023-07-24 12:02:13,805] {taskinstance.py:1358} INFO - 
--------------------------------------------------------------------------------
[2023-07-24 12:02:13,859] {taskinstance.py:1377} INFO - Executing <Task(PythonOperator): fetch_data> on 2023-07-24 12:01:56.805305+00:00
[2023-07-24 12:02:13,876] {standard_task_runner.py:52} INFO - Started process 4478 to run task
[2023-07-24 12:02:13,900] {standard_task_runner.py:79} INFO - Running: ['***', 'tasks', 'run', 'etl_dag', 'fetch_data', 'manual__2023-07-24T12:01:56.805305+00:00', '--job-id', '56', '--raw', '--subdir', 'DAGS_FOLDER/etl_dag.py', '--cfg-path', '/tmp/tmp07p9ku5b', '--error-file', '/tmp/tmpo2ylrx9o']
[2023-07-24 12:02:13,904] {standard_task_runner.py:80} INFO - Job 56: Subtask fetch_data
[2023-07-24 12:02:14,122] {task_command.py:370} INFO - Running <TaskInstance: etl_dag.fetch_data manual__2023-07-24T12:01:56.805305+00:00 [running]> on host c03236539c84
[2023-07-24 12:02:14,534] {taskinstance.py:1571} INFO - Exporting the following env vars:
AIRFLOW_CTX_DAG_OWNER=***
AIRFLOW_CTX_DAG_ID=etl_dag
AIRFLOW_CTX_TASK_ID=fetch_data
AIRFLOW_CTX_EXECUTION_DATE=2023-07-24T12:01:56.805305+00:00
AIRFLOW_CTX_TRY_NUMBER=1
AIRFLOW_CTX_DAG_RUN_ID=manual__2023-07-24T12:01:56.805305+00:00
[2023-07-24 12:02:14,679] {base.py:68} INFO - Using connection ID 'aws_default' for task execution.
[2023-07-24 12:02:14,681] {base_aws.py:206} INFO - Credentials retrieved from login
[2023-07-24 12:02:15,760] {taskinstance.py:1889} ERROR - Task failed with exception
Traceback (most recent call last):
  File "/home/airflow/.local/lib/python3.7/site-packages/airflow/operators/python.py", line 171, in execute
    return_value = self.execute_callable()
  File "/home/airflow/.local/lib/python3.7/site-packages/airflow/operators/python.py", line 189, in execute_callable
    return self.python_callable(*self.op_args, **self.op_kwargs)
  File "/opt/airflow/dags/etl_dag.py", line 62, in _fetch_data_upload_S3
    s3_hook.load_file(filename=data_logs_filename, key=filename, bucket_name=Variable.get("S3BucketName"))
  File "/home/airflow/.local/lib/python3.7/site-packages/airflow/providers/amazon/aws/hooks/s3.py", line 63, in wrapper
    return func(*bound_args.args, **bound_args.kwargs)
  File "/home/airflow/.local/lib/python3.7/site-packages/airflow/providers/amazon/aws/hooks/s3.py", line 91, in wrapper
    return func(*bound_args.args, **bound_args.kwargs)
  File "/home/airflow/.local/lib/python3.7/site-packages/airflow/providers/amazon/aws/hooks/s3.py", line 600, in load_file
    raise ValueError(f"The key {key} already exists.")
ValueError: The key Real_time_payments_1690187507.8259003.csv already exists.
[2023-07-24 12:02:15,814] {taskinstance.py:1400} INFO - Marking task as FAILED. dag_id=etl_dag, task_id=fetch_data, execution_date=20230724T120156, start_date=20230724T120213, end_date=20230724T120215
[2023-07-24 12:02:15,873] {standard_task_runner.py:97} ERROR - Failed to execute job 56 for task fetch_data (The key Real_time_payments_1690187507.8259003.csv already exists.; 4478)
[2023-07-24 12:02:15,932] {local_task_job.py:156} INFO - Task exited with return code 1
[2023-07-24 12:02:16,170] {local_task_job.py:273} INFO - 0 downstream tasks scheduled from follow-on schedule check
