[2023-07-24 12:04:55,939] {taskinstance.py:1159} INFO - Dependencies all met for <TaskInstance: etl_dag.fetch_data manual__2023-07-24T12:04:15.261964+00:00 [queued]>
[2023-07-24 12:04:56,315] {taskinstance.py:1159} INFO - Dependencies all met for <TaskInstance: etl_dag.fetch_data manual__2023-07-24T12:04:15.261964+00:00 [queued]>
[2023-07-24 12:04:56,322] {taskinstance.py:1356} INFO - 
--------------------------------------------------------------------------------
[2023-07-24 12:04:56,330] {taskinstance.py:1357} INFO - Starting attempt 1 of 1
[2023-07-24 12:04:56,343] {taskinstance.py:1358} INFO - 
--------------------------------------------------------------------------------
[2023-07-24 12:04:56,590] {taskinstance.py:1377} INFO - Executing <Task(PythonOperator): fetch_data> on 2023-07-24 12:04:15.261964+00:00
[2023-07-24 12:04:56,682] {standard_task_runner.py:52} INFO - Started process 4569 to run task
[2023-07-24 12:04:56,791] {standard_task_runner.py:79} INFO - Running: ['***', 'tasks', 'run', 'etl_dag', 'fetch_data', 'manual__2023-07-24T12:04:15.261964+00:00', '--job-id', '62', '--raw', '--subdir', 'DAGS_FOLDER/etl_dag.py', '--cfg-path', '/tmp/tmpld1vmaid', '--error-file', '/tmp/tmpcq_l98u3']
[2023-07-24 12:04:56,821] {standard_task_runner.py:80} INFO - Job 62: Subtask fetch_data
[2023-07-24 12:04:57,739] {task_command.py:370} INFO - Running <TaskInstance: etl_dag.fetch_data manual__2023-07-24T12:04:15.261964+00:00 [running]> on host c03236539c84
[2023-07-24 12:05:00,486] {taskinstance.py:1571} INFO - Exporting the following env vars:
AIRFLOW_CTX_DAG_OWNER=***
AIRFLOW_CTX_DAG_ID=etl_dag
AIRFLOW_CTX_TASK_ID=fetch_data
AIRFLOW_CTX_EXECUTION_DATE=2023-07-24T12:04:15.261964+00:00
AIRFLOW_CTX_TRY_NUMBER=1
AIRFLOW_CTX_DAG_RUN_ID=manual__2023-07-24T12:04:15.261964+00:00
[2023-07-24 12:05:03,368] {base.py:68} INFO - Using connection ID 'aws_default' for task execution.
[2023-07-24 12:05:03,416] {base_aws.py:206} INFO - Credentials retrieved from login
[2023-07-24 12:05:23,920] {taskinstance.py:1889} ERROR - Task failed with exception
Traceback (most recent call last):
  File "/home/airflow/.local/lib/python3.7/site-packages/airflow/operators/python.py", line 171, in execute
    return_value = self.execute_callable()
  File "/home/airflow/.local/lib/python3.7/site-packages/airflow/operators/python.py", line 189, in execute_callable
    return self.python_callable(*self.op_args, **self.op_kwargs)
  File "/opt/airflow/dags/etl_dag.py", line 62, in _fetch_data_upload_S3
    s3_hook.load_file(filename=data_logs_filename, key=filename, bucket_name=Variable.get("S3BucketName"))
  File "/home/airflow/.local/lib/python3.7/site-packages/airflow/providers/amazon/aws/hooks/s3.py", line 63, in wrapper
    return func(*bound_args.args, **bound_args.kwargs)
  File "/home/airflow/.local/lib/python3.7/site-packages/airflow/providers/amazon/aws/hooks/s3.py", line 91, in wrapper
    return func(*bound_args.args, **bound_args.kwargs)
  File "/home/airflow/.local/lib/python3.7/site-packages/airflow/providers/amazon/aws/hooks/s3.py", line 600, in load_file
    raise ValueError(f"The key {key} already exists.")
ValueError: The key Real_time_payments_1690187507.8259003.csv already exists.
[2023-07-24 12:05:24,246] {taskinstance.py:1400} INFO - Marking task as FAILED. dag_id=etl_dag, task_id=fetch_data, execution_date=20230724T120415, start_date=20230724T120455, end_date=20230724T120524
[2023-07-24 12:05:24,923] {standard_task_runner.py:97} ERROR - Failed to execute job 62 for task fetch_data (The key Real_time_payments_1690187507.8259003.csv already exists.; 4569)
[2023-07-24 12:05:25,395] {local_task_job.py:156} INFO - Task exited with return code 1
[2023-07-24 12:05:26,299] {local_task_job.py:273} INFO - 0 downstream tasks scheduled from follow-on schedule check
