[2023-07-24 09:52:09,569] {taskinstance.py:1159} INFO - Dependencies all met for <TaskInstance: etl_dag.fetch_data scheduled__2023-07-24T08:00:00+00:00 [queued]>
[2023-07-24 09:52:09,702] {taskinstance.py:1159} INFO - Dependencies all met for <TaskInstance: etl_dag.fetch_data scheduled__2023-07-24T08:00:00+00:00 [queued]>
[2023-07-24 09:52:09,703] {taskinstance.py:1356} INFO - 
--------------------------------------------------------------------------------
[2023-07-24 09:52:09,713] {taskinstance.py:1357} INFO - Starting attempt 1 of 1
[2023-07-24 09:52:09,719] {taskinstance.py:1358} INFO - 
--------------------------------------------------------------------------------
[2023-07-24 09:52:10,046] {taskinstance.py:1377} INFO - Executing <Task(PythonOperator): fetch_data> on 2023-07-24 08:00:00+00:00
[2023-07-24 09:52:10,202] {standard_task_runner.py:52} INFO - Started process 268 to run task
[2023-07-24 09:52:10,332] {standard_task_runner.py:79} INFO - Running: ['***', 'tasks', 'run', 'etl_dag', 'fetch_data', 'scheduled__2023-07-24T08:00:00+00:00', '--job-id', '7', '--raw', '--subdir', 'DAGS_FOLDER/etl_dag.py', '--cfg-path', '/tmp/tmpc764ot10', '--error-file', '/tmp/tmprx1c8o7g']
[2023-07-24 09:52:10,356] {standard_task_runner.py:80} INFO - Job 7: Subtask fetch_data
[2023-07-24 09:52:11,233] {task_command.py:370} INFO - Running <TaskInstance: etl_dag.fetch_data scheduled__2023-07-24T08:00:00+00:00 [running]> on host c03236539c84
[2023-07-24 09:52:12,962] {taskinstance.py:1571} INFO - Exporting the following env vars:
AIRFLOW_CTX_DAG_OWNER=***
AIRFLOW_CTX_DAG_ID=etl_dag
AIRFLOW_CTX_TASK_ID=fetch_data
AIRFLOW_CTX_EXECUTION_DATE=2023-07-24T08:00:00+00:00
AIRFLOW_CTX_TRY_NUMBER=1
AIRFLOW_CTX_DAG_RUN_ID=scheduled__2023-07-24T08:00:00+00:00
[2023-07-24 09:52:13,133] {taskinstance.py:1889} ERROR - Task failed with exception
Traceback (most recent call last):
  File "/home/airflow/.local/lib/python3.7/site-packages/airflow/operators/python.py", line 171, in execute
    return_value = self.execute_callable()
  File "/home/airflow/.local/lib/python3.7/site-packages/airflow/operators/python.py", line 189, in execute_callable
    return self.python_callable(*self.op_args, **self.op_kwargs)
  File "/opt/airflow/dags/etl_dag.py", line 57, in _fetch_data_upload_S3
    file = pd.read_csv('data_logs_filename')
  File "/home/airflow/.local/lib/python3.7/site-packages/pandas/util/_decorators.py", line 311, in wrapper
    return func(*args, **kwargs)
  File "/home/airflow/.local/lib/python3.7/site-packages/pandas/io/parsers/readers.py", line 586, in read_csv
    return _read(filepath_or_buffer, kwds)
  File "/home/airflow/.local/lib/python3.7/site-packages/pandas/io/parsers/readers.py", line 482, in _read
    parser = TextFileReader(filepath_or_buffer, **kwds)
  File "/home/airflow/.local/lib/python3.7/site-packages/pandas/io/parsers/readers.py", line 811, in __init__
    self._engine = self._make_engine(self.engine)
  File "/home/airflow/.local/lib/python3.7/site-packages/pandas/io/parsers/readers.py", line 1040, in _make_engine
    return mapping[engine](self.f, **self.options)  # type: ignore[call-arg]
  File "/home/airflow/.local/lib/python3.7/site-packages/pandas/io/parsers/c_parser_wrapper.py", line 51, in __init__
    self._open_handles(src, kwds)
  File "/home/airflow/.local/lib/python3.7/site-packages/pandas/io/parsers/base_parser.py", line 229, in _open_handles
    errors=kwds.get("encoding_errors", "strict"),
  File "/home/airflow/.local/lib/python3.7/site-packages/pandas/io/common.py", line 707, in get_handle
    newline="",
FileNotFoundError: [Errno 2] No such file or directory: 'data_logs_filename'
[2023-07-24 09:52:13,329] {taskinstance.py:1400} INFO - Marking task as FAILED. dag_id=etl_dag, task_id=fetch_data, execution_date=20230724T080000, start_date=20230724T095209, end_date=20230724T095213
[2023-07-24 09:52:13,498] {standard_task_runner.py:97} ERROR - Failed to execute job 7 for task fetch_data ([Errno 2] No such file or directory: 'data_logs_filename'; 268)
[2023-07-24 09:52:13,578] {local_task_job.py:156} INFO - Task exited with return code 1
[2023-07-24 09:52:14,243] {local_task_job.py:273} INFO - 0 downstream tasks scheduled from follow-on schedule check
[2023-07-24 09:55:02,673] {taskinstance.py:1159} INFO - Dependencies all met for <TaskInstance: etl_dag.fetch_data scheduled__2023-07-24T08:00:00+00:00 [queued]>
[2023-07-24 09:55:02,761] {taskinstance.py:1159} INFO - Dependencies all met for <TaskInstance: etl_dag.fetch_data scheduled__2023-07-24T08:00:00+00:00 [queued]>
[2023-07-24 09:55:02,768] {taskinstance.py:1356} INFO - 
--------------------------------------------------------------------------------
[2023-07-24 09:55:02,773] {taskinstance.py:1357} INFO - Starting attempt 1 of 1
[2023-07-24 09:55:02,781] {taskinstance.py:1358} INFO - 
--------------------------------------------------------------------------------
[2023-07-24 09:55:03,038] {taskinstance.py:1377} INFO - Executing <Task(PythonOperator): fetch_data> on 2023-07-24 08:00:00+00:00
[2023-07-24 09:55:03,070] {standard_task_runner.py:52} INFO - Started process 366 to run task
[2023-07-24 09:55:03,127] {standard_task_runner.py:79} INFO - Running: ['***', 'tasks', 'run', 'etl_dag', 'fetch_data', 'scheduled__2023-07-24T08:00:00+00:00', '--job-id', '12', '--raw', '--subdir', 'DAGS_FOLDER/etl_dag.py', '--cfg-path', '/tmp/tmplhw6o06p', '--error-file', '/tmp/tmp_92n_6eg']
[2023-07-24 09:55:03,223] {standard_task_runner.py:80} INFO - Job 12: Subtask fetch_data
[2023-07-24 09:55:03,955] {task_command.py:370} INFO - Running <TaskInstance: etl_dag.fetch_data scheduled__2023-07-24T08:00:00+00:00 [running]> on host c03236539c84
[2023-07-24 09:55:04,540] {taskinstance.py:1571} INFO - Exporting the following env vars:
AIRFLOW_CTX_DAG_OWNER=***
AIRFLOW_CTX_DAG_ID=etl_dag
AIRFLOW_CTX_TASK_ID=fetch_data
AIRFLOW_CTX_EXECUTION_DATE=2023-07-24T08:00:00+00:00
AIRFLOW_CTX_TRY_NUMBER=1
AIRFLOW_CTX_DAG_RUN_ID=scheduled__2023-07-24T08:00:00+00:00
[2023-07-24 09:55:05,077] {base_aws.py:447} WARNING - Unable to use Airflow Connection for credentials.
[2023-07-24 09:55:28,499] {taskinstance.py:1889} ERROR - Task failed with exception
Traceback (most recent call last):
  File "/home/airflow/.local/lib/python3.7/site-packages/airflow/operators/python.py", line 171, in execute
    return_value = self.execute_callable()
  File "/home/airflow/.local/lib/python3.7/site-packages/airflow/operators/python.py", line 189, in execute_callable
    return self.python_callable(*self.op_args, **self.op_kwargs)
  File "/opt/airflow/dags/etl_dag.py", line 63, in _fetch_data_upload_S3
    s3_hook.load_file(filename=file, key=filename, bucket_name=Variable.get("S3BucketName"))
  File "/home/airflow/.local/lib/python3.7/site-packages/airflow/providers/amazon/aws/hooks/s3.py", line 63, in wrapper
    return func(*bound_args.args, **bound_args.kwargs)
  File "/home/airflow/.local/lib/python3.7/site-packages/airflow/providers/amazon/aws/hooks/s3.py", line 91, in wrapper
    return func(*bound_args.args, **bound_args.kwargs)
  File "/home/airflow/.local/lib/python3.7/site-packages/airflow/providers/amazon/aws/hooks/s3.py", line 599, in load_file
    if not replace and self.check_for_key(key, bucket_name):
  File "/home/airflow/.local/lib/python3.7/site-packages/airflow/providers/amazon/aws/hooks/s3.py", line 63, in wrapper
    return func(*bound_args.args, **bound_args.kwargs)
  File "/home/airflow/.local/lib/python3.7/site-packages/airflow/providers/amazon/aws/hooks/s3.py", line 91, in wrapper
    return func(*bound_args.args, **bound_args.kwargs)
  File "/home/airflow/.local/lib/python3.7/site-packages/airflow/providers/amazon/aws/hooks/s3.py", line 442, in check_for_key
    obj = self.head_object(key, bucket_name)
  File "/home/airflow/.local/lib/python3.7/site-packages/airflow/providers/amazon/aws/hooks/s3.py", line 63, in wrapper
    return func(*bound_args.args, **bound_args.kwargs)
  File "/home/airflow/.local/lib/python3.7/site-packages/airflow/providers/amazon/aws/hooks/s3.py", line 91, in wrapper
    return func(*bound_args.args, **bound_args.kwargs)
  File "/home/airflow/.local/lib/python3.7/site-packages/airflow/providers/amazon/aws/hooks/s3.py", line 424, in head_object
    return self.get_conn().head_object(Bucket=bucket_name, Key=key)
  File "/home/airflow/.local/lib/python3.7/site-packages/botocore/client.py", line 508, in _api_call
    return self._make_api_call(operation_name, kwargs)
  File "/home/airflow/.local/lib/python3.7/site-packages/botocore/client.py", line 899, in _make_api_call
    operation_model, request_dict, request_context
  File "/home/airflow/.local/lib/python3.7/site-packages/botocore/client.py", line 921, in _make_request
    return self._endpoint.make_request(operation_model, request_dict)
  File "/home/airflow/.local/lib/python3.7/site-packages/botocore/endpoint.py", line 119, in make_request
    return self._send_request(request_dict, operation_model)
  File "/home/airflow/.local/lib/python3.7/site-packages/botocore/endpoint.py", line 198, in _send_request
    request = self.create_request(request_dict, operation_model)
  File "/home/airflow/.local/lib/python3.7/site-packages/botocore/endpoint.py", line 137, in create_request
    operation_name=operation_model.name,
  File "/home/airflow/.local/lib/python3.7/site-packages/botocore/hooks.py", line 412, in emit
    return self._emitter.emit(aliased_event_name, **kwargs)
  File "/home/airflow/.local/lib/python3.7/site-packages/botocore/hooks.py", line 256, in emit
    return self._emit(event_name, kwargs)
  File "/home/airflow/.local/lib/python3.7/site-packages/botocore/hooks.py", line 239, in _emit
    response = handler(**kwargs)
  File "/home/airflow/.local/lib/python3.7/site-packages/botocore/signers.py", line 103, in handler
    return self.sign(operation_name, request)
  File "/home/airflow/.local/lib/python3.7/site-packages/botocore/signers.py", line 187, in sign
    auth.add_auth(request)
  File "/home/airflow/.local/lib/python3.7/site-packages/botocore/auth.py", line 407, in add_auth
    raise NoCredentialsError()
botocore.exceptions.NoCredentialsError: Unable to locate credentials
[2023-07-24 09:55:28,760] {taskinstance.py:1400} INFO - Marking task as FAILED. dag_id=etl_dag, task_id=fetch_data, execution_date=20230724T080000, start_date=20230724T095502, end_date=20230724T095528
[2023-07-24 09:55:28,940] {standard_task_runner.py:97} ERROR - Failed to execute job 12 for task fetch_data (Unable to locate credentials; 366)
[2023-07-24 09:55:29,173] {local_task_job.py:156} INFO - Task exited with return code 1
[2023-07-24 09:55:29,979] {local_task_job.py:273} INFO - 0 downstream tasks scheduled from follow-on schedule check
