[2023-07-24 13:05:16,150] {taskinstance.py:1159} INFO - Dependencies all met for <TaskInstance: etl_dag.transfer_data_to_postgres scheduled__2023-07-24T12:00:00+00:00 [queued]>
[2023-07-24 13:05:16,217] {taskinstance.py:1159} INFO - Dependencies all met for <TaskInstance: etl_dag.transfer_data_to_postgres scheduled__2023-07-24T12:00:00+00:00 [queued]>
[2023-07-24 13:05:16,224] {taskinstance.py:1356} INFO - 
--------------------------------------------------------------------------------
[2023-07-24 13:05:16,225] {taskinstance.py:1357} INFO - Starting attempt 1 of 1
[2023-07-24 13:05:16,226] {taskinstance.py:1358} INFO - 
--------------------------------------------------------------------------------
[2023-07-24 13:05:16,299] {taskinstance.py:1377} INFO - Executing <Task(S3ToPostgresOperator): transfer_data_to_postgres> on 2023-07-24 12:00:00+00:00
[2023-07-24 13:05:16,333] {standard_task_runner.py:52} INFO - Started process 240 to run task
[2023-07-24 13:05:16,388] {standard_task_runner.py:79} INFO - Running: ['***', 'tasks', 'run', 'etl_dag', 'transfer_data_to_postgres', 'scheduled__2023-07-24T12:00:00+00:00', '--job-id', '103', '--raw', '--subdir', 'DAGS_FOLDER/etl_dag.py', '--cfg-path', '/tmp/tmp9a583ser', '--error-file', '/tmp/tmp_mngqgoc']
[2023-07-24 13:05:16,403] {standard_task_runner.py:80} INFO - Job 103: Subtask transfer_data_to_postgres
[2023-07-24 13:05:16,901] {task_command.py:370} INFO - Running <TaskInstance: etl_dag.transfer_data_to_postgres scheduled__2023-07-24T12:00:00+00:00 [running]> on host 58d73bc824ec
[2023-07-24 13:05:18,365] {taskinstance.py:1571} INFO - Exporting the following env vars:
AIRFLOW_CTX_DAG_OWNER=***
AIRFLOW_CTX_DAG_ID=etl_dag
AIRFLOW_CTX_TASK_ID=transfer_data_to_postgres
AIRFLOW_CTX_EXECUTION_DATE=2023-07-24T12:00:00+00:00
AIRFLOW_CTX_TRY_NUMBER=1
AIRFLOW_CTX_DAG_RUN_ID=scheduled__2023-07-24T12:00:00+00:00
[2023-07-24 13:05:18,401] {s3.py:861} INFO - Downloading source S3 file from Bucket lead-project-bucket-ojo with path Real_time_payments_1690201757.765383.csv
[2023-07-24 13:05:18,546] {base.py:68} INFO - Using connection ID 'aws_default' for task execution.
[2023-07-24 13:05:18,561] {base_aws.py:206} INFO - Credentials retrieved from login
[2023-07-24 13:05:22,385] {base.py:68} INFO - Using connection ID 'postgres://cazwrmravtstuq:***@ec2-54-234-13-16.compute-1.amazonaws.com:5432/d7ojfso4s2fmat' for task execution.
[2023-07-24 13:05:25,018] {taskinstance.py:1889} ERROR - Task failed with exception
Traceback (most recent call last):
  File "/home/airflow/.local/lib/python3.7/site-packages/sqlalchemy/engine/base.py", line 1706, in _execute_context
    cursor, statement, parameters, context
  File "/home/airflow/.local/lib/python3.7/site-packages/sqlalchemy/engine/default.py", line 716, in do_execute
    cursor.execute(statement, parameters)
psycopg2.errors.UniqueViolation: duplicate key value violates unique constraint "pg_type_typname_nsp_index"
DETAIL:  Key (typname, typnamespace)=(real_time_data_3, 51592473) already exists.


The above exception was the direct cause of the following exception:

Traceback (most recent call last):
  File "/opt/airflow/plugins/s3toPostgres.py", line 42, in execute
    df_file.to_sql(self.table, engine, if_exists="replace", index=False)
  File "/home/airflow/.local/lib/python3.7/site-packages/pandas/core/generic.py", line 2882, in to_sql
    method=method,
  File "/home/airflow/.local/lib/python3.7/site-packages/pandas/io/sql.py", line 728, in to_sql
    **engine_kwargs,
  File "/home/airflow/.local/lib/python3.7/site-packages/pandas/io/sql.py", line 1758, in to_sql
    dtype=dtype,
  File "/home/airflow/.local/lib/python3.7/site-packages/pandas/io/sql.py", line 1650, in prep_table
    table.create()
  File "/home/airflow/.local/lib/python3.7/site-packages/pandas/io/sql.py", line 867, in create
    self._execute_create()
  File "/home/airflow/.local/lib/python3.7/site-packages/pandas/io/sql.py", line 853, in _execute_create
    self.table.create()
  File "/home/airflow/.local/lib/python3.7/site-packages/sqlalchemy/sql/schema.py", line 943, in create
    bind._run_ddl_visitor(ddl.SchemaGenerator, self, checkfirst=checkfirst)
  File "/home/airflow/.local/lib/python3.7/site-packages/sqlalchemy/engine/base.py", line 3008, in _run_ddl_visitor
    conn._run_ddl_visitor(visitorcallable, element, **kwargs)
  File "/home/airflow/.local/lib/python3.7/site-packages/sqlalchemy/engine/base.py", line 2016, in _run_ddl_visitor
    visitorcallable(self.dialect, self, **kwargs).traverse_single(element)
  File "/home/airflow/.local/lib/python3.7/site-packages/sqlalchemy/sql/visitors.py", line 483, in traverse_single
    return meth(obj, **kw)
  File "/home/airflow/.local/lib/python3.7/site-packages/sqlalchemy/sql/ddl.py", line 895, in visit_table
    include_foreign_key_constraints,  # noqa
  File "/home/airflow/.local/lib/python3.7/site-packages/sqlalchemy/engine/base.py", line 1200, in execute
    return meth(self, multiparams, params, _EMPTY_EXECUTION_OPTS)
  File "/home/airflow/.local/lib/python3.7/site-packages/sqlalchemy/sql/ddl.py", line 78, in _execute_on_connection
    self, multiparams, params, execution_options
  File "/home/airflow/.local/lib/python3.7/site-packages/sqlalchemy/engine/base.py", line 1296, in _execute_ddl
    compiled,
  File "/home/airflow/.local/lib/python3.7/site-packages/sqlalchemy/engine/base.py", line 1749, in _execute_context
    e, statement, parameters, cursor, context
  File "/home/airflow/.local/lib/python3.7/site-packages/sqlalchemy/engine/base.py", line 1930, in _handle_dbapi_exception
    sqlalchemy_exception, with_traceback=exc_info[2], from_=e
  File "/home/airflow/.local/lib/python3.7/site-packages/sqlalchemy/util/compat.py", line 211, in raise_
    raise exception
  File "/home/airflow/.local/lib/python3.7/site-packages/sqlalchemy/engine/base.py", line 1706, in _execute_context
    cursor, statement, parameters, context
  File "/home/airflow/.local/lib/python3.7/site-packages/sqlalchemy/engine/default.py", line 716, in do_execute
    cursor.execute(statement, parameters)
sqlalchemy.exc.IntegrityError: (psycopg2.errors.UniqueViolation) duplicate key value violates unique constraint "pg_type_typname_nsp_index"
DETAIL:  Key (typname, typnamespace)=(real_time_data_3, 51592473) already exists.

[SQL: 
CREATE TABLE real_time_data_3 (
	cc_num BIGINT, 
	merchant TEXT, 
	category TEXT, 
	amt FLOAT(53), 
	first TEXT, 
	last TEXT, 
	gender TEXT, 
	street TEXT, 
	city TEXT, 
	state TEXT, 
	zip BIGINT, 
	lat FLOAT(53), 
	long FLOAT(53), 
	city_pop BIGINT, 
	job TEXT, 
	dob TEXT, 
	trans_num TEXT, 
	merch_lat FLOAT(53), 
	merch_long FLOAT(53), 
	is_fraud BIGINT, 
	"current_time" BIGINT, 
	trans_date_trans_time TEXT, 
	unix_time BIGINT, 
	prediction BIGINT
)

]
(Background on this error at: http://sqlalche.me/e/14/gkpj)
[2023-07-24 13:05:25,109] {taskinstance.py:1400} INFO - Marking task as FAILED. dag_id=etl_dag, task_id=transfer_data_to_postgres, execution_date=20230724T120000, start_date=20230724T130516, end_date=20230724T130525
[2023-07-24 13:05:25,191] {standard_task_runner.py:97} ERROR - Failed to execute job 103 for task transfer_data_to_postgres ((psycopg2.errors.UniqueViolation) duplicate key value violates unique constraint "pg_type_typname_nsp_index"
DETAIL:  Key (typname, typnamespace)=(real_time_data_3, 51592473) already exists.

[SQL: 
CREATE TABLE real_time_data_3 (
	cc_num BIGINT, 
	merchant TEXT, 
	category TEXT, 
	amt FLOAT(53), 
	first TEXT, 
	last TEXT, 
	gender TEXT, 
	street TEXT, 
	city TEXT, 
	state TEXT, 
	zip BIGINT, 
	lat FLOAT(53), 
	long FLOAT(53), 
	city_pop BIGINT, 
	job TEXT, 
	dob TEXT, 
	trans_num TEXT, 
	merch_lat FLOAT(53), 
	merch_long FLOAT(53), 
	is_fraud BIGINT, 
	"current_time" BIGINT, 
	trans_date_trans_time TEXT, 
	unix_time BIGINT, 
	prediction BIGINT
)

]
(Background on this error at: http://sqlalche.me/e/14/gkpj); 240)
[2023-07-24 13:05:25,313] {local_task_job.py:156} INFO - Task exited with return code 1
[2023-07-24 13:05:25,616] {local_task_job.py:273} INFO - 0 downstream tasks scheduled from follow-on schedule check
