[2023-07-24 09:52:09,766] {taskinstance.py:1159} INFO - Dependencies all met for <TaskInstance: etl_dag.fetch_data manual__2023-07-24T09:51:40.501718+00:00 [queued]>
[2023-07-24 09:52:09,998] {taskinstance.py:1159} INFO - Dependencies all met for <TaskInstance: etl_dag.fetch_data manual__2023-07-24T09:51:40.501718+00:00 [queued]>
[2023-07-24 09:52:10,009] {taskinstance.py:1356} INFO - 
--------------------------------------------------------------------------------
[2023-07-24 09:52:10,011] {taskinstance.py:1357} INFO - Starting attempt 1 of 1
[2023-07-24 09:52:10,012] {taskinstance.py:1358} INFO - 
--------------------------------------------------------------------------------
[2023-07-24 09:52:10,405] {taskinstance.py:1377} INFO - Executing <Task(PythonOperator): fetch_data> on 2023-07-24 09:51:40.501718+00:00
[2023-07-24 09:52:10,473] {standard_task_runner.py:52} INFO - Started process 269 to run task
[2023-07-24 09:52:10,545] {standard_task_runner.py:79} INFO - Running: ['***', 'tasks', 'run', 'etl_dag', 'fetch_data', 'manual__2023-07-24T09:51:40.501718+00:00', '--job-id', '8', '--raw', '--subdir', 'DAGS_FOLDER/etl_dag.py', '--cfg-path', '/tmp/tmp4ykfpg_u', '--error-file', '/tmp/tmpflqo42xe']
[2023-07-24 09:52:10,569] {standard_task_runner.py:80} INFO - Job 8: Subtask fetch_data
[2023-07-24 09:52:12,152] {task_command.py:370} INFO - Running <TaskInstance: etl_dag.fetch_data manual__2023-07-24T09:51:40.501718+00:00 [running]> on host c03236539c84
[2023-07-24 09:52:13,586] {taskinstance.py:1571} INFO - Exporting the following env vars:
AIRFLOW_CTX_DAG_OWNER=***
AIRFLOW_CTX_DAG_ID=etl_dag
AIRFLOW_CTX_TASK_ID=fetch_data
AIRFLOW_CTX_EXECUTION_DATE=2023-07-24T09:51:40.501718+00:00
AIRFLOW_CTX_TRY_NUMBER=1
AIRFLOW_CTX_DAG_RUN_ID=manual__2023-07-24T09:51:40.501718+00:00
[2023-07-24 09:52:13,717] {taskinstance.py:1889} ERROR - Task failed with exception
Traceback (most recent call last):
  File "/home/airflow/.local/lib/python3.7/site-packages/airflow/operators/python.py", line 171, in execute
    return_value = self.execute_callable()
  File "/home/airflow/.local/lib/python3.7/site-packages/airflow/operators/python.py", line 189, in execute_callable
    return self.python_callable(*self.op_args, **self.op_kwargs)
  File "/opt/airflow/dags/etl_dag.py", line 57, in _fetch_data_upload_S3
    file = pd.read_csv('data_logs_filename')
  File "/home/airflow/.local/lib/python3.7/site-packages/pandas/util/_decorators.py", line 311, in wrapper
    return func(*args, **kwargs)
  File "/home/airflow/.local/lib/python3.7/site-packages/pandas/io/parsers/readers.py", line 586, in read_csv
    return _read(filepath_or_buffer, kwds)
  File "/home/airflow/.local/lib/python3.7/site-packages/pandas/io/parsers/readers.py", line 482, in _read
    parser = TextFileReader(filepath_or_buffer, **kwds)
  File "/home/airflow/.local/lib/python3.7/site-packages/pandas/io/parsers/readers.py", line 811, in __init__
    self._engine = self._make_engine(self.engine)
  File "/home/airflow/.local/lib/python3.7/site-packages/pandas/io/parsers/readers.py", line 1040, in _make_engine
    return mapping[engine](self.f, **self.options)  # type: ignore[call-arg]
  File "/home/airflow/.local/lib/python3.7/site-packages/pandas/io/parsers/c_parser_wrapper.py", line 51, in __init__
    self._open_handles(src, kwds)
  File "/home/airflow/.local/lib/python3.7/site-packages/pandas/io/parsers/base_parser.py", line 229, in _open_handles
    errors=kwds.get("encoding_errors", "strict"),
  File "/home/airflow/.local/lib/python3.7/site-packages/pandas/io/common.py", line 707, in get_handle
    newline="",
FileNotFoundError: [Errno 2] No such file or directory: 'data_logs_filename'
[2023-07-24 09:52:13,898] {taskinstance.py:1400} INFO - Marking task as FAILED. dag_id=etl_dag, task_id=fetch_data, execution_date=20230724T095140, start_date=20230724T095209, end_date=20230724T095213
[2023-07-24 09:52:13,984] {standard_task_runner.py:97} ERROR - Failed to execute job 8 for task fetch_data ([Errno 2] No such file or directory: 'data_logs_filename'; 269)
[2023-07-24 09:52:14,100] {local_task_job.py:156} INFO - Task exited with return code 1
[2023-07-24 09:52:14,675] {local_task_job.py:273} INFO - 0 downstream tasks scheduled from follow-on schedule check
